Workbook

Sheet LISEZMOI
B1: Base de données CGPP RDC : riposte à la MVE-17 (virus Bundibugyo)
B2: Canevas de la base Excel normalisée : une feuille par table, une ligne par observation, des identifiants stables. Les scripts Python du dossier « scripts » lisent et écrivent ces feuilles.
B4: Légende
C5: En-tête bleu foncé : nom technique de la colonne (ne pas modifier). Survoler l'en-tête pour lire la description.
C6: Fond jaune : cellule à saisir (ligne d'exemple en italique, à supprimer avant usage).
C7: Fond gris : cellule calculée par formule (ne pas saisir).
C8: Fond bleu pâle : référentiel tenu par l'équipe SI (zones, indicateurs, semaines).
B10: Qui remplit quoi
B11: saisie_hebdo | C11: Points focaux des IP, chaque vendredi (dimanche au plus tard) : une ligne par indicateur, ZS et semaine ; numérateur ET dénominateur pour les pourcentages.
B12: sbc_activites / sbc_synthese_as | C12: Export de la fiche SBC journalière (ODK), une ligne par site visité et une ligne par aire de santé et par jour.
B13: reunions / points_action | C13: Représentant CGPP à chaque réunion : la réunion, puis chaque point d'action avec responsable, échéance et statut.
B14: sitrep_notes | C14: Équipe SI : faits marquants, défis et actions repris dans le SitRep CGPP.
B15: feuilles sitrep_*, epi_*, … | C15: Remplies automatiquement par le script s01 à partir des SitReps nationaux : ne pas saisir à la main.
B16: tableau_suivi | C16: Calculé par formules à partir de saisie_hebdo et ref_indicateurs.
B17: qc_suivi | C17: Alimentée par le contrôle qualité (s03) ; l'équipe complète responsable, statut et date de résolution.
B19: Règles de saisie
B20: 1. Une valeur par cellule ; pas de texte dans les colonnes numériques ; pas de cellules fusionnées.
B21: 2. Les codes (province, ZS, partenaire, indicateur) viennent des listes déroulantes.
B22: 3. Un pourcentage se saisit toujours en numérateur et dénominateur, jamais en pourcentage tout fait.
B23: 4. Une semaine se renseigne même si la valeur est zéro : une cellule vide signifie « non rapporté ».
B25: Commandes
B26: python pipeline.py (extraction, contrôle qualité, analyses et SitRep CGPP)
B27: python pipeline.py --etapes qc,sitrep (relancer seulement le contrôle et le SitRep)
B29: Canevas généré le 12/10/2026 ; modèle de données : 22 tables.

Sheet tableau_suivi
A1: Suivi des indicateurs : calculé à partir de la feuille saisie_hebdo
A2: Les pourcentages sont recalculés à partir de la somme des numérateurs et de la somme des dénominateurs (jamais en additionnant des pourcentages). Ne rien saisir dans cette feuille.
A4: id_indicateur | B4: pilier | C4: indicateur | D4: type | E4: cible DOS | F4: cible DOS (nombre) | G4: numérateur cumulé | H4: dénominateur cumulé | I4: réalisé | J4: % de la cible | K4: dernière semaine saisie | L4: lignes saisies | M4: statut
A5: =IFERROR(INDEX(ref_indicateurs!$A:$A,2)&"","") | B5: =IF($A5="","",INDEX(ref_indicateurs!$B:$B,MATCH($A5,ref_indicateurs!$A:$A,0))&"") | C5: =IF($A5="","",INDEX(ref_indicateurs!$C:$C,MATCH($A5,ref_indicateurs!$A:$A,0))&"") | D5: =IF($A5="","",INDEX(ref_indicateurs!$E:$E,MATCH($A5,ref_indicateurs!$A:$A,0))&"") | E5: =IF($A5="","",INDEX(ref_indicateurs!$M:$M,MATCH($A5,ref_indicateurs!$A:$A,0))&"") | F5: =IF($A5="","",IF(INDEX(ref_indicateurs!$O:$O,MATCH($A5,ref_indicateurs!$A:$A,0))="","",INDEX(ref_indicateurs!$O:$O,MATCH($A5,ref_indicateurs!$A:$A,0)))) | G5: =IF($A5="","",SUMIFS(saisie_hebdo!$L:$L,saisie_hebdo!$I:$I,$A5)) | H5: =IF($A5="","",SUMIFS(saisie_hebdo!$M:$M,saisie_hebdo!$I:$I,$A5)) | I5: =IF(OR($A5="",L5=0),"",IF(D5="Pourcentage",IF(H5>0,G5/H5*100,""),G5)) | J5: =IF(OR(I5="",F5="",F5=0),"",I5/F5) | K5: =IF(OR($A5="",L5=0),"",IF(_xlfn.MAXIFS(saisie_hebdo!$C:$C,saisie_hebdo!$I:$I,$A5)=0,"",_xlfn.MAXIFS(saisie_hebdo!$C:$C,saisie_hebdo!$I:$I,$A5))) | L5: =IF($A5="","",COUNTIFS(saisie_hebdo!$I:$I,$A5)) | M5: =IF($A5="","",IF(L5=0,"Non rapporté",IF(F5="","Suivi sans cible",IF(D5="Pourcentage",IF(I5>=F5,"Cible atteinte","Sous la cible"),IF(J5>=1,"Cible atteinte","En cours")))))
A6: =IFERROR(INDEX(ref_indicateurs!$A:$A,3)&"","") | B6: =IF($A6="","",INDEX(ref_indicateurs!$B:$B,MATCH($A6,ref_indicateurs!$A:$A,0))&"") | C6: =IF($A6="","",INDEX(ref_indicateurs!$C:$C,MATCH($A6,ref_indicateurs!$A:$A,0))&"") | D6: =IF($A6="","",INDEX(ref_indicateurs!$E:$E,MATCH($A6,ref_indicateurs!$A:$A,0))&"") | E6: =IF($A6="","",INDEX(ref_indicateurs!$M:$M,MATCH($A6,ref_indicateurs!$A:$A,0))&"") | F6: =IF($A6="","",IF(INDEX(ref_indicateurs!$O:$O,MATCH($A6,ref_indicateurs!$A:$A,0))="","",INDEX(ref_indicateurs!$O:$O,MATCH($A6,ref_indicateurs!$A:$A,0)))) | G6: =IF($A6="","",SUMIFS(saisie_hebdo!$L:$L,saisie_hebdo!$I:$I,$A6)) | H6: =IF($A6="","",SUMIFS(saisie_hebdo!$M:$M,saisie_hebdo!$I:$I,$A6)) | I6: =IF(OR($A6="",L6=0),"",IF(D6="Pourcentage",IF(H6>0,G6/H6*100,""),G6)) | J6: =IF(OR(I6="",F6="",F6=0),"",I6/F6) | K6: =IF(OR($A6="",L6=0),"",IF(_xlfn.MAXIFS(saisie_hebdo!$C:$C,saisie_hebdo!$I:$I,$A6)=0,"",_xlfn.MAXIFS(saisie_hebdo!$C:$C,saisie_hebdo!$I:$I,$A6))) | L6: =IF($A6="","",COUNTIFS(saisie_hebdo!$I:$I,$A6)) | M6: =IF($A6="","",IF(L6=0,"Non rapporté",IF(F6="","Suivi sans cible",IF(D6="Pourcentage",IF(I6>=F6,"Cible atteinte","Sous la cible"),IF(J6>=1,"Cible atteinte","En cours")))))
A7: =IFERROR(INDEX(ref_indicateurs!$A:$A,4)&"","") | B7: =IF($A7="","",INDEX(ref_indicateurs!$B:$B,MATCH($A7,ref_indicateurs!$A:$A,0))&"") | C7: =IF($A7="","",INDEX(ref_indicateurs!$C:$C,MATCH($A7,ref_indicateurs!$A:$A,0))&"") | D7: =IF($A7="","",INDEX(ref_indicateurs!$E:$E,MATCH($A7,ref_indicateurs!$A:$A,0))&"") | E7: =IF($A7="","",INDEX(ref_indicateurs!$M:$M,MATCH($A7,ref_indicateurs!$A:$A,0))&"") | F7: =IF($A7="","",IF(INDEX(ref_indicateurs!$O:$O,MATCH($A7,ref_indicateurs!$A:$A,0))="","",INDEX(ref_indicateurs!$O:$O,MATCH($A7,ref_indicateurs!$A:$A,0)))) | G7: =IF($A7="","",SUMIFS(saisie_hebdo!$L:$L,saisie_hebdo!$I:$I,$A7)) | H7: =IF($A7="","",SUMIFS(saisie_hebdo!$M:$M,saisie_hebdo!$I:$I,$A7)) | I7: =IF(OR($A7="",L7=0),"",IF(D7="Pourcentage",IF(H7>0,G7/H7*100,""),G7)) | J7: =IF(OR(I7="",F7="",F7=0),"",I7/F7) | K7: =IF(OR($A7="",L7=0),"",IF(_xlfn.MAXIFS(saisie_hebdo!$C:$C,saisie_hebdo!$I:$I,$A7)=0,"",_xlfn.MAXIFS(saisie_hebdo!$C:$C,saisie_hebdo!$I:$I,$A7))) | L7: =IF($A7="","",COUNTIFS(saisie_hebdo!$I:$I,$A7)) | M7: =IF($A7="","",IF(L7=0,"Non rapporté",IF(F7="","Suivi sans cible",IF(D7="Pourcentage",IF(I7>=F7,"Cible atteinte","Sous la cible"),IF(J7>=1,"Cible atteinte","En cours")))))
A8: =IFERROR(INDEX(ref_indicateurs!$A:$A,5)&"","") | B8: =IF($A8="","",INDEX(ref_indicateurs!$B:$B,MATCH($A8,ref_indicateurs!$A:$A,0))&"") | C8: =IF($A8="","",INDEX(ref_indicateurs!$C:$C,MATCH($A8,ref_indicateurs!$A:$A,0))&"") | D8: =IF($A8="","",INDEX(ref_indicateurs!$E:$E,MATCH($A8,ref_indicateurs!$A:$A,0))&"") | E8: =IF($A8="","",INDEX(ref_indicateurs!$M:$M,MATCH($A8,ref_indicateurs!$A:$A,0))&"") | F8: =IF($A8="","",IF(INDEX(ref_indicateurs!$O:$O,MATCH($A8,ref_indicateurs!$A:$A,0))="","",INDEX(ref_indicateurs!$O:$O,MATCH($A8,ref_indicateurs!$A:$A,0)))) | G8: =IF($A8="","",SUMIFS(saisie_hebdo!$L:$L,saisie_hebdo!$I:$I,$A8)) | H8: =IF($A8="","",SUMIFS(saisie_hebdo!$M:$M,saisie_hebdo!$I:$I,$A8)) | I8: =IF(OR($A8="",L8=0),"",IF(D8="Pourcentage",IF(H8>0,G8/H8*100,""),G8)) | J8: =IF(OR(I8="",F8="",F8=0),"",I8/F8) | K8: =IF(OR($A8="",L8=0),"",IF(_xlfn.MAXIFS(saisie_hebdo!$C:$C,saisie_hebdo!$I:$I,$A8)=0,"",_xlfn.MAXIFS(saisie_hebdo!$C:$C,saisie_hebdo!$I:$I,$A8))) | L8: =IF($A8="","",COUNTIFS(saisie_hebdo!$I:$I,$A8)) | M8: =IF($A8="","",IF(L8=0,"Non rapporté",IF(F8="","Suivi sans cible",IF(D8="Pourcentage",IF(I8>=F8,"Cible atteinte","Sous la cible"),IF(J8>=1,"Cible atteinte","En cours")))))
A9: =IFERROR(INDEX(ref_indicateurs!$A:$A,6)&"","") | B9: =IF($A9="","",INDEX(ref_indicateurs!$B:$B,MATCH($A9,ref_indicateurs!$A:$A,0))&"") | C9: =IF($A9="","",INDEX(ref_indicateurs!$C:$C,MATCH($A9,ref_indicateurs!$A:$A,0))&"") | D9: =IF($A9="","",INDEX(ref_indicateurs!$E:$E,MATCH($A9,ref_indicateurs!$A:$A,0))&"") | E9: =IF($A9="","",INDEX(ref_indicateurs!$M:$M,MATCH($A9,ref_indicateurs!$A:$A,0))&"") | F9: =IF($A9="","",IF(INDEX(ref_indicateurs!$O:$O,MATCH($A9,ref_indicateurs!$A:$A,0))="","",INDEX(ref_indicateurs!$O:$O,MATCH($A9,ref_indicateurs!$A:$A,0)))) | G9: =IF($A9="","",SUMIFS(saisie_hebdo!$L:$L,saisie_hebdo!$I:$I,$A9)) | H9: =IF($A9="","",SUMIFS(saisie_hebdo!$M:$M,saisie_hebdo!$I:$I,$A9)) | I9: =IF(OR($A9="",L9=0),"",IF(D9="Pourcentage",IF(H9>0,G9/H9*100,""),G9)) | J9: =IF(OR(I9="",F9="",F9=0),"",I9/F9) | K9: =IF(OR($A9="",L9=0),"",IF(_xlfn.MAXIFS(saisie_hebdo!$C:$C,saisie_hebdo!$I:$I,$A9)=0,"",_xlfn.MAXIFS(saisie_hebdo!$C:$C,saisie_hebdo!$I:$I,$A9))) | L9: =IF($A9="","",COUNTIFS(saisie_hebdo!$I:$I,$A9)) | M9: =IF($A9="","",IF(L9=0,"Non rapporté",IF(F9="","Suivi sans cible",IF(D9="Pourcentage",IF(I9>=F9,"Cible atteinte","Sous la cible"),IF(J9>=1,"Cible atteinte","En cours")))))
A10: =IFERROR(INDEX(ref_indicateurs!$A:$A,7)&"","") | B10: =IF($A10="","",INDEX(ref_indicateurs!$B:$B,MATCH($A10,ref_indicateurs!$A:$A,0))&"") | C10: =IF($A10="","",INDEX(ref_indicateurs!$C:$C,MATCH($A10,ref_indicateurs!$A:$A,0))&"") | D10: =IF($A10="","",INDEX(ref_indicateurs!$E:$E,MATCH($A10,ref_indicateurs!$A:$A,0))&"") | E10: =IF($A10="","",INDEX(ref_indicateurs!$M:$M,MATCH($A10,ref_indicateurs!$A:$A,0))&"") | F10: =IF($A10="","",IF(INDEX(ref_indicateurs!$O:$O,MATCH($A10,ref_indicateurs!$A:$A,0))="","",INDEX(ref_indicateurs!$O:$O,MATCH($A10,ref_indicateurs!$A:$A,0)))) | G10: =IF($A10="","",SUMIFS(saisie_hebdo!$L:$L,saisie_hebdo!$I:$I,$A10)) | H10: =IF($A10="","",SUMIFS(saisie_hebdo!$M:$M,saisie_hebdo!$I:$I,$A10)) | I10: =IF(OR($A10="",L10=0),"",IF(D10="Pourcentage",IF(H10>0,G10/H10*100,""),G10)) | J10: =IF(OR(I10="",F10="",F10=0),"",I10/F10) | K10: =IF(OR($A10="",L10=0),"",IF(_xlfn.MAXIFS(saisie_hebdo!$C:$C,saisie_hebdo!$I:$I,$A10)=0,"",_xlfn.MAXIFS(saisie_hebdo!$C:$C,saisie_hebdo!$I:$I,$A10))) | L10: =IF($A10="","",COUNTIFS(saisie_hebdo!$I:$I,$A10)) | M10: =IF($A10="","",IF(L10=0,"Non rapporté",IF(F10="","Suivi sans cible",IF(D10="Pourcentage",IF(I10>=F10,"Cible atteinte","Sous la cible"),IF(J10>=1,"Cible atteinte","En cours")))))
A11: =IFERROR(INDEX(ref_indicateurs!$A:$A,8)&"","") | B11: =IF($A11="","",INDEX(ref_indicateurs!$B:$B,MATCH($A11,ref_indicateurs!$A:$A,0))&"") | C11: =IF($A11="","",INDEX(ref_indicateurs!$C:$C,MATCH($A11,ref_indicateurs!$A:$A,0))&"") | D11: =IF($A11="","",INDEX(ref_indicateurs!$E:$E,MATCH($A11,ref_indicateurs!$A:$A,0))&"") | E11: =IF($A11="","",INDEX(ref_indicateurs!$M:$M,MATCH($A11,ref_indicateurs!$A:$A,0))&"") | F11: =IF($A11="","",IF(INDEX(ref_indicateurs!$O:$O,MATCH($A11,ref_indicateurs!$A:$A,0))="","",INDEX(ref_indicateurs!$O:$O,MATCH($A11,ref_indicateurs!$A:$A,0)))) | G11: =IF($A11="","",SUMIFS(saisie_hebdo!$L:$L,saisie_hebdo!$I:$I,$A11)) | H11: =IF($A11="","",SUMIFS(saisie_hebdo!$M:$M,saisie_hebdo!$I:$I,$A11)) | I11: =IF(OR($A11="",L11=0),"",IF(D11="Pourcentage",IF(H11>0,G11/H11*100,""),G11)) | J11: =IF(OR(I11="",F11="",F11=0),"",I11/F11) | K11: =IF(OR($A11="",L11=0),"",IF(_xlfn.MAXIFS(saisie_hebdo!$C:$C,saisie_hebdo!$I:$I,$A11)=0,"",_xlfn.MAXIFS(saisie_hebdo!$C:$C,saisie_hebdo!$I:$I,$A11))) | L11: =IF($A11="","",COUNTIFS(saisie_hebdo!$I:$I,$A11)) | M11: =IF($A11="","",IF(L11=0,"Non rapporté",IF(F11="","Suivi sans cible",IF(D11="Pourcentage",IF(I11>=F11,"Cible atteinte","Sous la cible"),IF(J11>=1,"Cible atteinte","En cours")))))
A12: =IFERROR(INDEX(ref_indicateurs!$A:$A,9)&"","") | B12: =IF($A12="","",INDEX(ref_indicateurs!$B:$B,MATCH($A12,ref_indicateurs!$A:$A,0))&"") | C12: =IF($A12="","",INDEX(ref_indicateurs!$C:$C,MATCH($A12,ref_indicateurs!$A:$A,0))&"") | D12: =IF($A12="","",INDEX(ref_indicateurs!$E:$E,MATCH($A12,ref_indicateurs!$A:$A,0))&"") | E12: =IF($A12="","",INDEX(ref_indicateurs!$M:$M,MATCH($A12,ref_indicateurs!$A:$A,0))&"") | F12: =IF($A12="","",IF(INDEX(ref_indicateurs!$O:$O,MATCH($A12,ref_indicateurs!$A:$A,0))="","",INDEX(ref_indicateurs!$O:$O,MATCH($A12,ref_indicateurs!$A:$A,0)))) | G12: =IF($A12="","",SUMIFS(saisie_hebdo!$L:$L,saisie_hebdo!$I:$I,$A12)) | H12: =IF($A12="","",SUMIFS(saisie_hebdo!$M:$M,saisie_hebdo!$I:$I,$A12)) | I12: =IF(OR($A12="",L12=0),"",IF(D12="Pourcentage",IF(H12>0,G12/H12*100,""),G12)) | J12: =IF(OR(I12="",F12="",F12=0),"",I12/F12) | K12: =IF(OR($A12="",L12=0),"",IF(_xlfn.MAXIFS(saisie_hebdo!$C:$C,saisie_hebdo!$I:$I,$A12)=0,"",_xlfn.MAXIFS(saisie_hebdo!$C:$C,saisie_hebdo!$I:$I,$A12))) | L12: =IF($A12="","",COUNTIFS(saisie_hebdo!$I:$I,$A12)) | M12: =IF($A12="","",IF(L12=0,"Non rapporté",IF(F12="","Suivi sans cible",IF(D12="Pourcentage",IF(I12>=F12,"Cible atteinte","Sous la cible"),IF(J12>=1,"Cible atteinte","En cours")))))
A13: =IFERROR(INDEX(ref_indicateurs!$A:$A,10)&"","") | B13: =IF($A13="","",INDEX(ref_indicateurs!$B:$B,MATCH($A13,ref_indicateurs!$A:$A,0))&"") | C13: =IF($A13="","",INDEX(ref_indicateurs!$C:$C,MATCH($A13,ref_indicateurs!$A:$A,0))&"") | D13: =IF($A13="","",INDEX(ref_indicateurs!$E:$E,MATCH($A13,ref_indicateurs!$A:$A,0))&"") | E13: =IF($A13="","",INDEX(ref_indicateurs!$M:$M,MATCH($A13,ref_indicateurs!$A:$A,0))&"") | F13: =IF($A13="","",IF(INDEX(ref_indicateurs!$O:$O,MATCH($A13,ref_indicateurs!$A:$A,0))="","",INDEX(ref_indicateurs!$O:$O,MATCH($A13,ref_indicateurs!$A:$A,0)))) | G13: =IF($A13="","",SUMIFS(saisie_hebdo!$L:$L,saisie_hebdo!$I:$I,$A13)) | H13: =IF($A13="","",SUMIFS(saisie_hebdo!$M:$M,saisie_hebdo!$I:$I,$A13)) | I13: =IF(OR($A13="",L13=0),"",IF(D13="Pourcentage",IF(H13>0,G13/H13*100,""),G13)) | J13: =IF(OR(I13="",F13="",F13=0),"",I13/F13) | K13: =IF(OR($A13="",L13=0),"",IF(_xlfn.MAXIFS(saisie_hebdo!$C:$C,saisie_hebdo!$I:$I,$A13)=0,"",_xlfn.MAXIFS(saisie_hebdo!$C:$C,saisie_hebdo!$I:$I,$A13))) | L13: =IF($A13="","",COUNTIFS(saisie_hebdo!$I:$I,$A13)) | M13: =IF($A13="","",IF(L13=0,"Non rapporté",IF(F13="","Suivi sans cible",IF(D13="Pourcentage",IF(I13>=F13,"Cible atteinte","Sous la cible"),IF(J13>=1,"Cible atteinte","En cours")))))
A14: =IFERROR(INDEX(ref_indicateurs!$A:$A,11)&"","") | B14: =IF($A14="","",INDEX(ref_indicateurs!$B:$B,MATCH($A14,ref_indicateurs!$A:$A,0))&"") | C14: =IF($A14="","",INDEX(ref_indicateurs!$C:$C,MATCH($A14,ref_indicateurs!$A:$A,0))&"") | D14: =IF($A14="","",INDEX(ref_indicateurs!$E:$E,MATCH($A14,ref_indicateurs!$A:$A,0))&"") | E14: =IF($A14="","",INDEX(ref_indicateurs!$M:$M,MATCH($A14,ref_indicateurs!$A:$A,0))&"") | F14: =IF($A14="","",IF(INDEX(ref_indicateurs!$O:$O,MATCH($A14,ref_indicateurs!$A:$A,0))="","",INDEX(ref_indicateurs!$O:$O,MATCH($A14,ref_indicateurs!$A:$A,0)))) | G14: =IF($A14="","",SUMIFS(saisie_hebdo!$L:$L,saisie_hebdo!$I:$I,$A14)) | H14: =IF($A14="","",SUMIFS(saisie_hebdo!$M:$M,saisie_hebdo!$I:$I,$A14)) | I14: =IF(OR($A14="",L14=0),"",IF(D14="Pourcentage",IF(H14>0,G14/H14*100,""),G14)) | J14: =IF(OR(I14="",F14="",F14=0),"",I14/F14) | K14: =IF(OR($A14="",L14=0),"",IF(_xlfn.MAXIFS(saisie_hebdo!$C:$C,saisie_hebdo!$I:$I,$A14)=0,"",_xlfn.MAXIFS(saisie_hebdo!$C:$C,saisie_hebdo!$I:$I,$A14))) | L14: =IF($A14="","",COUNTIFS(saisie_hebdo!$I:$I,$A14)) | M14: =IF($A14="","",IF(L14=0,"Non rapporté",IF(F14="","Suivi sans cible",IF(D14="Pourcentage",IF(I14>=F14,"Cible atteinte","Sous la cible"),IF(J14>=1,"Cible atteinte","En cours")))))
A15: =IFERROR(INDEX(ref_indicateurs!$A:$A,12)&"","") | B15: =IF($A15="","",INDEX(ref_indicateurs!$B:$B,MATCH($A15,ref_indicateurs!$A:$A,0))&"") | C15: =IF($A15="","",INDEX(ref_indicateurs!$C:$C,MATCH($A15,ref_indicateurs!$A:$A,0))&"") | D15: =IF($A15="","",INDEX(ref_indicateurs!$E:$E,MATCH($A15,ref_indicateurs!$A:$A,0))&"") | E15: =IF($A15="","",INDEX(ref_indicateurs!$M:$M,MATCH($A15,ref_indicateurs!$A:$A,0))&"") | F15: =IF($A15="","",IF(INDEX(ref_indicateurs!$O:$O,MATCH($A15,ref_indicateurs!$A:$A,0))="","",INDEX(ref_indicateurs!$O:$O,MATCH($A15,ref_indicateurs!$A:$A,0)))) | G15: =IF($A15="","",SUMIFS(saisie_hebdo!$L:$L,saisie_hebdo!$I:$I,$A15)) | H15: =IF($A15="","",SUMIFS(saisie_hebdo!$M:$M,saisie_hebdo!$I:$I,$A15)) | I15: =IF(OR($A15="",L15=0),"",IF(D15="Pourcentage",IF(H15>0,G15/H15*100,""),G15)) | J15: =IF(OR(I15="",F15="",F15=0),"",I15/F15) | K15: =IF(OR($A15="",L15=0),"",IF(_xlfn.MAXIFS(saisie_hebdo!$C:$C,saisie_hebdo!$I:$I,$A15)=0,"",_xlfn.MAXIFS(saisie_hebdo!$C:$C,saisie_hebdo!$I:$I,$A15))) | L15: =IF($A15="","",COUNTIFS(saisie_hebdo!$I:$I,$A15)) | M15: =IF($A15="","",IF(L15=0,"Non rapporté",IF(F15="","Suivi sans cible",IF(D15="Pourcentage",IF(I15>=F15,"Cible atteinte","Sous la cible"),IF(J15>=1,"Cible atteinte","En cours")))))
A16: =IFERROR(INDEX(ref_indicateurs!$A:$A,13)&"","") | B16: =IF($A16="","",INDEX(ref_indicateurs!$B:$B,MATCH($A16,ref_indicateurs!$A:$A,0))&"") | C16: =IF($A16="","",INDEX(ref_indicateurs!$C:$C,MATCH($A16,ref_indicateurs!$A:$A,0))&"") | D16: =IF($A16="","",INDEX(ref_indicateurs!$E:$E,MATCH($A16,ref_indicateurs!$A:$A,0))&"") | E16: =IF($A16="","",INDEX(ref_indicateurs!$M:$M,MATCH($A16,ref_indicateurs!$A:$A,0))&"") | F16: =IF($A16="","",IF(INDEX(ref_indicateurs!$O:$O,MATCH($A16,ref_indicateurs!$A:$A,0))="","",INDEX(ref_indicateurs!$O:$O,MATCH($A16,ref_indicateurs!$A:$A,0)))) | G16: =IF($A16="","",SUMIFS(saisie_hebdo!$L:$L,saisie_hebdo!$I:$I,$A16)) | H16: =IF($A16="","",SUMIFS(saisie_hebdo!$M:$M,saisie_hebdo!$I:$I,$A16)) | I16: =IF(OR($A16="",L16=0),"",IF(D16="Pourcentage",IF(H16>0,G16/H16*100,""),G16)) | J16: =IF(OR(I16="",F16="",F16=0),"",I16/F16) | K16: =IF(OR($A16="",L16=0),"",IF(_xlfn.MAXIFS(saisie_hebdo!$C:$C,saisie_hebdo!$I:$I,$A16)=0,"",_xlfn.MAXIFS(saisie_hebdo!$C:$C,saisie_hebdo!$I:$I,$A16))) | L16: =IF($A16="","",COUNTIFS(saisie_hebdo!$I:$I,$A16)) | M16: =IF($A16="","",IF(L16=0,"Non rapporté",IF(F16="","Suivi sans cible",IF(D16="Pourcentage",IF(I16>=F16,"Cible atteinte","Sous la cible"),IF(J16>=1,"Cible atteinte","En cours")))))
A17: =IFERROR(INDEX(ref_indicateurs!$A:$A,14)&"","") | B17: =IF($A17="","",INDEX(ref_indicateurs!$B:$B,MATCH($A17,ref_indicateurs!$A:$A,0))&"") | C17: =IF($A17="","",INDEX(ref_indicateurs!$C:$C,MATCH($A17,ref_indicateurs!$A:$A,0))&"") | D17: =IF($A17="","",INDEX(ref_indicateurs!$E:$E,MATCH($A17,ref_indicateurs!$A:$A,0))&"") | E17: =IF($A17="","",INDEX(ref_indicateurs!$M:$M,MATCH($A17,ref_indicateurs!$A:$A,0))&"") | F17: =IF($A17="","",IF(INDEX(ref_indicateurs!$O:$O,MATCH($A17,ref_indicateurs!$A:$A,0))="","",INDEX(ref_indicateurs!$O:$O,MATCH($A17,ref_indicateurs!$A:$A,0)))) | G17: =IF($A17="","",SUMIFS(saisie_hebdo!$L:$L,saisie_hebdo!$I:$I,$A17)) | H17: =IF($A17="","",SUMIFS(saisie_hebdo!$M:$M,saisie_hebdo!$I:$I,$A17)) | I17: =IF(OR($A17="",L17=0),"",IF(D17="Pourcentage",IF(H17>0,G17/H17*100,""),G17)) | J17: =IF(OR(I17="",F17="",F17=0),"",I17/F17) | K17: =IF(OR($A17="",L17=0),"",IF(_xlfn.MAXIFS(saisie_hebdo!$C:$C,saisie_hebdo!$I:$I,$A17)=0,"",_xlfn.MAXIFS(saisie_hebdo!$C:$C,saisie_hebdo!$I:$I,$A17))) | L17: =IF($A17="","",COUNTIFS(saisie_hebdo!$I:$I,$A17)) | M17: =IF($A17="","",IF(L17=0,"Non rapporté",IF(F17="","Suivi sans cible",IF(D17="Pourcentage",IF(I17>=F17,"Cible atteinte","Sous la cible"),IF(J17>=1,"Cible atteinte","En cours")))))
A18: =IFERROR(INDEX(ref_indicateurs!$A:$A,15)&"","") | B18: =IF($A18="","",INDEX(ref_indicateurs!$B:$B,MATCH($A18,ref_indicateurs!$A:$A,0))&"") | C18: =IF($A18="","",INDEX(ref_indicateurs!$C:$C,MATCH($A18,ref_indicateurs!$A:$A,0))&"") | D18: =IF($A18="","",INDEX(ref_indicateurs!$E:$E,MATCH($A18,ref_indicateurs!$A:$A,0))&"") | E18: =IF($A18="","",INDEX(ref_indicateurs!$M:$M,MATCH($A18,ref_indicateurs!$A:$A,0))&"") | F18: =IF($A18="","",IF(INDEX(ref_indicateurs!$O:$O,MATCH($A18,ref_indicateurs!$A:$A,0))="","",INDEX(ref_indicateurs!$O:$O,MATCH($A18,ref_indicateurs!$A:$A,0)))) | G18: =IF($A18="","",SUMIFS(saisie_hebdo!$L:$L,saisie_hebdo!$I:$I,$A18)) | H18: =IF($A18="","",SUMIFS(saisie_hebdo!$M:$M,saisie_hebdo!$I:$I,$A18)) | I18: =IF(OR($A18="",L18=0),"",IF(D18="Pourcentage",IF(H18>0,G18/H18*100,""),G18)) | J18: =IF(OR(I18="",F18="",F18=0),"",I18/F18) | K18: =IF(OR($A18="",L18=0),"",IF(_xlfn.MAXIFS(saisie_hebdo!$C:$C,saisie_hebdo!$I:$I,$A18)=0,"",_xlfn.MAXIFS(saisie_hebdo!$C:$C,saisie_hebdo!$I:$I,$A18))) | L18: =IF($A18="","",COUNTIFS(saisie_hebdo!$I:$I,$A18)) | M18: =IF($A18="","",IF(L18=0,"Non rapporté",IF(F18="","Suivi sans cible",IF(D18="Pourcentage",IF(I18>=F18,"Cible atteinte","Sous la cible"),IF(J18>=1,"Cible atteinte","En cours")))))
A19: =IFERROR(INDEX(ref_indicateurs!$A:$A,16)&"","") | B19: =IF($A19="","",INDEX(ref_indicateurs!$B:$B,MATCH($A19,ref_indicateurs!$A:$A,0))&"") | C19: =IF($A19="","",INDEX(ref_indicateurs!$C:$C,MATCH($A19,ref_indicateurs!$A:$A,0))&"") | D19: =IF($A19="","",INDEX(ref_indicateurs!$E:$E,MATCH($A19,ref_indicateurs!$A:$A,0))&"") | E19: =IF($A19="","",INDEX(ref_indicateurs!$M:$M,MATCH($A19,ref_indicateurs!$A:$A,0))&"") | F19: =IF($A19="","",IF(INDEX(ref_indicateurs!$O:$O,MATCH($A19,ref_indicateurs!$A:$A,0))="","",INDEX(ref_indicateurs!$O:$O,MATCH($A19,ref_indicateurs!$A:$A,0)))) | G19: =IF($A19="","",SUMIFS(saisie_hebdo!$L:$L,saisie_hebdo!$I:$I,$A19)) | H19: =IF($A19="","",SUMIFS(saisie_hebdo!$M:$M,saisie_hebdo!$I:$I,$A19)) | I19: =IF(OR($A19="",L19=0),"",IF(D19="Pourcentage",IF(H19>0,G19/H19*100,""),G19)) | J19: =IF(OR(I19="",F19="",F19=0),"",I19/F19) | K19: =IF(OR($A19="",L19=0),"",IF(_xlfn.MAXIFS(saisie_hebdo!$C:$C,saisie_hebdo!$I:$I,$A19)=0,"",_xlfn.MAXIFS(saisie_hebdo!$C:$C,saisie_hebdo!$I:$I,$A19))) | L19: =IF($A19="","",COUNTIFS(saisie_hebdo!$I:$I,$A19)) | M19: =IF($A19="","",IF(L19=0,"Non rapporté",IF(F19="","Suivi sans cible",IF(D19="Pourcentage",IF(I19>=F19,"Cible atteinte","Sous la cible"),IF(J19>=1,"Cible atteinte","En cours")))))
A20: =IFERROR(INDEX(ref_indicateurs!$A:$A,17)&"","") | B20: =IF($A20="","",INDEX(ref_indicateurs!$B:$B,MATCH($A20,ref_indicateurs!$A:$A,0))&"") | C20: =IF($A20="","",INDEX(ref_indicateurs!$C:$C,MATCH($A20,ref_indicateurs!$A:$A,0))&"") | D20: =IF($A20="","",INDEX(ref_indicateurs!$E:$E,MATCH($A20,ref_indicateurs!$A:$A,0))&"") | E20: =IF($A20="","",INDEX(ref_indicateurs!$M:$M,MATCH($A20,ref_indicateurs!$A:$A,0))&"") | F20: =IF($A20="","",IF(INDEX(ref_indicateurs!$O:$O,MATCH($A20,ref_indicateurs!$A:$A,0))="","",INDEX(ref_indicateurs!$O:$O,MATCH($A20,ref_indicateurs!$A:$A,0)))) | G20: =IF($A20="","",SUMIFS(saisie_hebdo!$L:$L,saisie_hebdo!$I:$I,$A20)) | H20: =IF($A20="","",SUMIFS(saisie_hebdo!$M:$M,saisie_hebdo!$I:$I,$A20)) | I20: =IF(OR($A20="",L20=0),"",IF(D20="Pourcentage",IF(H20>0,G20/H20*100,""),G20)) | J20: =IF(OR(I20="",F20="",F20=0),"",I20/F20) | K20: =IF(OR($A20="",L20=0),"",IF(_xlfn.MAXIFS(saisie_hebdo!$C:$C,saisie_hebdo!$I:$I,$A20)=0,"",_xlfn.MAXIFS(saisie_hebdo!$C:$C,saisie_hebdo!$I:$I,$A20))) | L20: =IF($A20="","",COUNTIFS(saisie_hebdo!$I:$I,$A20)) | M20: =IF($A20="","",IF(L20=0,"Non rapporté",IF(F20="","Suivi sans cible",IF(D20="Pourcentage",IF(I20>=F20,"Cible atteinte","Sous la cible"),IF(J20>=1,"Cible atteinte","En cours")))))
A21: =IFERROR(INDEX(ref_indicateurs!$A:$A,18)&"","") | B21: =IF($A21="","",INDEX(ref_indicateurs!$B:$B,MATCH($A21,ref_indicateurs!$A:$A,0))&"") | C21: =IF($A21="","",INDEX(ref_indicateurs!$C:$C,MATCH($A21,ref_indicateurs!$A:$A,0))&"") | D21: =IF($A21="","",INDEX(ref_indicateurs!$E:$E,MATCH($A21,ref_indicateurs!$A:$A,0))&"") | E21: =IF($A21="","",INDEX(ref_indicateurs!$M:$M,MATCH($A21,ref_indicateurs!$A:$A,0))&"") | F21: =IF($A21="","",IF(INDEX(ref_indicateurs!$O:$O,MATCH($A21,ref_indicateurs!$A:$A,0))="","",INDEX(ref_indicateurs!$O:$O,MATCH($A21,ref_indicateurs!$A:$A,0)))) | G21: =IF($A21="","",SUMIFS(saisie_hebdo!$L:$L,saisie_hebdo!$I:$I,$A21)) | H21: =IF($A21="","",SUMIFS(saisie_hebdo!$M:$M,saisie_hebdo!$I:$I,$A21)) | I21: =IF(OR($A21="",L21=0),"",IF(D21="Pourcentage",IF(H21>0,G21/H21*100,""),G21)) | J21: =IF(OR(I21="",F21="",F21=0),"",I21/F21) | K21: =IF(OR($A21="",L21=0),"",IF(_xlfn.MAXIFS(saisie_hebdo!$C:$C,saisie_hebdo!$I:$I,$A21)=0,"",_xlfn.MAXIFS(saisie_hebdo!$C:$C,saisie_hebdo!$I:$I,$A21))) | L21: =IF($A21="","",COUNTIFS(saisie_hebdo!$I:$I,$A21)) | M21: =IF($A21="","",IF(L21=0,"Non rapporté",IF(F21="","Suivi sans cible",IF(D21="Pourcentage",IF(I21>=F21,"Cible atteinte","Sous la cible"),IF(J21>=1,"Cible atteinte","En cours")))))
A22: =IFERROR(INDEX(ref_indicateurs!$A:$A,19)&"","") | B22: =IF($A22="","",INDEX(ref_indicateurs!$B:$B,MATCH($A22,ref_indicateurs!$A:$A,0))&"") | C22: =IF($A22="","",INDEX(ref_indicateurs!$C:$C,MATCH($A22,ref_indicateurs!$A:$A,0))&"") | D22: =IF($A22="","",INDEX(ref_indicateurs!$E:$E,MATCH($A22,ref_indicateurs!$A:$A,0))&"") | E22: =IF($A22="","",INDEX(ref_indicateurs!$M:$M,MATCH($A22,ref_indicateurs!$A:$A,0))&"") | F22: =IF($A22="","",IF(INDEX(ref_indicateurs!$O:$O,MATCH($A22,ref_indicateurs!$A:$A,0))="","",INDEX(ref_indicateurs!$O:$O,MATCH($A22,ref_indicateurs!$A:$A,0)))) | G22: =IF($A22="","",SUMIFS(saisie_hebdo!$L:$L,saisie_hebdo!$I:$I,$A22)) | H22: =IF($A22="","",SUMIFS(saisie_hebdo!$M:$M,saisie_hebdo!$I:$I,$A22)) | I22: =IF(OR($A22="",L22=0),"",IF(D22="Pourcentage",IF(H22>0,G22/H22*100,""),G22)) | J22: =IF(OR(I22="",F22="",F22=0),"",I22/F22) | K22: =IF(OR($A22="",L22=0),"",IF(_xlfn.MAXIFS(saisie_hebdo!$C:$C,saisie_hebdo!$I:$I,$A22)=0,"",_xlfn.MAXIFS(saisie_hebdo!$C:$C,saisie_hebdo!$I:$I,$A22))) | L22: =IF($A22="","",COUNTIFS(saisie_hebdo!$I:$I,$A22)) | M22: =IF($A22="","",IF(L22=0,"Non rapporté",IF(F22="","Suivi sans cible",IF(D22="Pourcentage",IF(I22>=F22,"Cible atteinte","Sous la cible"),IF(J22>=1,"Cible atteinte","En cours")))))
A23: =IFERROR(INDEX(ref_indicateurs!$A:$A,20)&"","") | B23: =IF($A23="","",INDEX(ref_indicateurs!$B:$B,MATCH($A23,ref_indicateurs!$A:$A,0))&"") | C23: =IF($A23="","",INDEX(ref_indicateurs!$C:$C,MATCH($A23,ref_indicateurs!$A:$A,0))&"") | D23: =IF($A23="","",INDEX(ref_indicateurs!$E:$E,MATCH($A23,ref_indicateurs!$A:$A,0))&"") | E23: =IF($A23="","",INDEX(ref_indicateurs!$M:$M,MATCH($A23,ref_indicateurs!$A:$A,0))&"") | F23: =IF($A23="","",IF(INDEX(ref_indicateurs!$O:$O,MATCH($A23,ref_indicateurs!$A:$A,0))="","",INDEX(ref_indicateurs!$O:$O,MATCH($A23,ref_indicateurs!$A:$A,0)))) | G23: =IF($A23="","",SUMIFS(saisie_hebdo!$L:$L,saisie_hebdo!$I:$I,$A23)) | H23: =IF($A23="","",SUMIFS(saisie_hebdo!$M:$M,saisie_hebdo!$I:$I,$A23)) | I23: =IF(OR($A23="",L23=0),"",IF(D23="Pourcentage",IF(H23>0,G23/H23*100,""),G23)) | J23: =IF(OR(I23="",F23="",F23=0),"",I23/F23) | K23: =IF(OR($A23="",L23=0),"",IF(_xlfn.MAXIFS(saisie_hebdo!$C:$C,saisie_hebdo!$I:$I,$A23)=0,"",_xlfn.MAXIFS(saisie_hebdo!$C:$C,saisie_hebdo!$I:$I,$A23))) | L23: =IF($A23="","",COUNTIFS(saisie_hebdo!$I:$I,$A23)) | M23: =IF($A23="","",IF(L23=0,"Non rapporté",IF(F23="","Suivi sans cible",IF(D23="Pourcentage",IF(I23>=F23,"Cible atteinte","Sous la cible"),IF(J23>=1,"Cible atteinte","En cours")))))
A24: =IFERROR(INDEX(ref_indicateurs!$A:$A,21)&"","") | B24: =IF($A24="","",INDEX(ref_indicateurs!$B:$B,MATCH($A24,ref_indicateurs!$A:$A,0))&"") | C24: =IF($A24="","",INDEX(ref_indicateurs!$C:$C,MATCH($A24,ref_indicateurs!$A:$A,0))&"") | D24: =IF($A24="","",INDEX(ref_indicateurs!$E:$E,MATCH($A24,ref_indicateurs!$A:$A,0))&"") | E24: =IF($A24="","",INDEX(ref_indicateurs!$M:$M,MATCH($A24,ref_indicateurs!$A:$A,0))&"") | F24: =IF($A24="","",IF(INDEX(ref_indicateurs!$O:$O,MATCH($A24,ref_indicateurs!$A:$A,0))="","",INDEX(ref_indicateurs!$O:$O,MATCH($A24,ref_indicateurs!$A:$A,0)))) | G24: =IF($A24="","",SUMIFS(saisie_hebdo!$L:$L,saisie_hebdo!$I:$I,$A24)) | H24: =IF($A24="","",SUMIFS(saisie_hebdo!$M:$M,saisie_hebdo!$I:$I,$A24)) | I24: =IF(OR($A24="",L24=0),"",IF(D24="Pourcentage",IF(H24>0,G24/H24*100,""),G24)) | J24: =IF(OR(I24="",F24="",F24=0),"",I24/F24) | K24: =IF(OR($A24="",L24=0),"",IF(_xlfn.MAXIFS(saisie_hebdo!$C:$C,saisie_hebdo!$I:$I,$A24)=0,"",_xlfn.MAXIFS(saisie_hebdo!$C:$C,saisie_hebdo!$I:$I,$A24))) | L24: =IF($A24="","",COUNTIFS(saisie_hebdo!$I:$I,$A24)) | M24: =IF($A24="","",IF(L24=0,"Non rapporté",IF(F24="","Suivi sans cible",IF(D24="Pourcentage",IF(I24>=F24,"Cible atteinte","Sous la cible"),IF(J24>=1,"Cible atteinte","En cours")))))
A25: =IFERROR(INDEX(ref_indicateurs!$A:$A,22)&"","") | B25: =IF($A25="","",INDEX(ref_indicateurs!$B:$B,MATCH($A25,ref_indicateurs!$A:$A,0))&"") | C25: =IF($A25="","",INDEX(ref_indicateurs!$C:$C,MATCH($A25,ref_indicateurs!$A:$A,0))&"") | D25: =IF($A25="","",INDEX(ref_indicateurs!$E:$E,MATCH($A25,ref_indicateurs!$A:$A,0))&"") | E25: =IF($A25="","",INDEX(ref_indicateurs!$M:$M,MATCH($A25,ref_indicateurs!$A:$A,0))&"") | F25: =IF($A25="","",IF(INDEX(ref_indicateurs!$O:$O,MATCH($A25,ref_indicateurs!$A:$A,0))="","",INDEX(ref_indicateurs!$O:$O,MATCH($A25,ref_indicateurs!$A:$A,0)))) | G25: =IF($A25="","",SUMIFS(saisie_hebdo!$L:$L,saisie_hebdo!$I:$I,$A25)) | H25: =IF($A25="","",SUMIFS(saisie_hebdo!$M:$M,saisie_hebdo!$I:$I,$A25)) | I25: =IF(OR($A25="",L25=0),"",IF(D25="Pourcentage",IF(H25>0,G25/H25*100,""),G25)) | J25: =IF(OR(I25="",F25="",F25=0),"",I25/F25) | K25: =IF(OR($A25="",L25=0),"",IF(_xlfn.MAXIFS(saisie_hebdo!$C:$C,saisie_hebdo!$I:$I,$A25)=0,"",_xlfn.MAXIFS(saisie_hebdo!$C:$C,saisie_hebdo!$I:$I,$A25))) | L25: =IF($A25="","",COUNTIFS(saisie_hebdo!$I:$I,$A25)) | M25: =IF($A25="","",IF(L25=0,"Non rapporté",IF(F25="","Suivi sans cible",IF(D25="Pourcentage",IF(I25>=F25,"Cible atteinte","Sous la cible"),IF(J25>=1,"Cible atteinte","En cours")))))
A26: =IFERROR(INDEX(ref_indicateurs!$A:$A,23)&"","") | B26: =IF($A26="","",INDEX(ref_indicateurs!$B:$B,MATCH($A26,ref_indicateurs!$A:$A,0))&"") | C26: =IF($A26="","",INDEX(ref_indicateurs!$C:$C,MATCH($A26,ref_indicateurs!$A:$A,0))&"") | D26: =IF($A26="","",INDEX(ref_indicateurs!$E:$E,MATCH($A26,ref_indicateurs!$A:$A,0))&"") | E26: =IF($A26="","",INDEX(ref_indicateurs!$M:$M,MATCH($A26,ref_indicateurs!$A:$A,0))&"") | F26: =IF($A26="","",IF(INDEX(ref_indicateurs!$O:$O,MATCH($A26,ref_indicateurs!$A:$A,0))="","",INDEX(ref_indicateurs!$O:$O,MATCH($A26,ref_indicateurs!$A:$A,0)))) | G26: =IF($A26="","",SUMIFS(saisie_hebdo!$L:$L,saisie_hebdo!$I:$I,$A26)) | H26: =IF($A26="","",SUMIFS(saisie_hebdo!$M:$M,saisie_hebdo!$I:$I,$A26)) | I26: =IF(OR($A26="",L26=0),"",IF(D26="Pourcentage",IF(H26>0,G26/H26*100,""),G26)) | J26: =IF(OR(I26="",F26="",F26=0),"",I26/F26) | K26: =IF(OR($A26="",L26=0),"",IF(_xlfn.MAXIFS(saisie_hebdo!$C:$C,saisie_hebdo!$I:$I,$A26)=0,"",_xlfn.MAXIFS(saisie_hebdo!$C:$C,saisie_hebdo!$I:$I,$A26))) | L26: =IF($A26="","",COUNTIFS(saisie_hebdo!$I:$I,$A26)) | M26: =IF($A26="","",IF(L26=0,"Non rapporté",IF(F26="","Suivi sans cible",IF(D26="Pourcentage",IF(I26>=F26,"Cible atteinte","Sous la cible"),IF(J26>=1,"Cible atteinte","En cours")))))
A27: =IFERROR(INDEX(ref_indicateurs!$A:$A,24)&"","") | B27: =IF($A27="","",INDEX(ref_indicateurs!$B:$B,MATCH($A27,ref_indicateurs!$A:$A,0))&"") | C27: =IF($A27="","",INDEX(ref_indicateurs!$C:$C,MATCH($A27,ref_indicateurs!$A:$A,0))&"") | D27: =IF($A27="","",INDEX(ref_indicateurs!$E:$E,MATCH($A27,ref_indicateurs!$A:$A,0))&"") | E27: =IF($A27="","",INDEX(ref_indicateurs!$M:$M,MATCH($A27,ref_indicateurs!$A:$A,0))&"") | F27: =IF($A27="","",IF(INDEX(ref_indicateurs!$O:$O,MATCH($A27,ref_indicateurs!$A:$A,0))="","",INDEX(ref_indicateurs!$O:$O,MATCH($A27,ref_indicateurs!$A:$A,0)))) | G27: =IF($A27="","",SUMIFS(saisie_hebdo!$L:$L,saisie_hebdo!$I:$I,$A27)) | H27: =IF($A27="","",SUMIFS(saisie_hebdo!$M:$M,saisie_hebdo!$I:$I,$A27)) | I27: =IF(OR($A27="",L27=0),"",IF(D27="Pourcentage",IF(H27>0,G27/H27*100,""),G27)) | J27: =IF(OR(I27="",F27="",F27=0),"",I27/F27) | K27: =IF(OR($A27="",L27=0),"",IF(_xlfn.MAXIFS(saisie_hebdo!$C:$C,saisie_hebdo!$I:$I,$A27)=0,"",_xlfn.MAXIFS(saisie_hebdo!$C:$C,saisie_hebdo!$I:$I,$A27))) | L27: =IF($A27="","",COUNTIFS(saisie_hebdo!$I:$I,$A27)) | M27: =IF($A27="","",IF(L27=0,"Non rapporté",IF(F27="","Suivi sans cible",IF(D27="Pourcentage",IF(I27>=F27,"Cible atteinte","Sous la cible"),IF(J27>=1,"Cible atteinte","En cours")))))
A28: =IFERROR(INDEX(ref_indicateurs!$A:$A,25)&"","") | B28: =IF($A28="","",INDEX(ref_indicateurs!$B:$B,MATCH($A28,ref_indicateurs!$A:$A,0))&"") | C28: =IF($A28="","",INDEX(ref_indicateurs!$C:$C,MATCH($A28,ref_indicateurs!$A:$A,0))&"") | D28: =IF($A28="","",INDEX(ref_indicateurs!$E:$E,MATCH($A28,ref_indicateurs!$A:$A,0))&"") | E28: =IF($A28="","",INDEX(ref_indicateurs!$M:$M,MATCH($A28,ref_indicateurs!$A:$A,0))&"") | F28: =IF($A28="","",IF(INDEX(ref_indicateurs!$O:$O,MATCH($A28,ref_indicateurs!$A:$A,0))="","",INDEX(ref_indicateurs!$O:$O,MATCH($A28,ref_indicateurs!$A:$A,0)))) | G28: =IF($A28="","",SUMIFS(saisie_hebdo!$L:$L,saisie_hebdo!$I:$I,$A28)) | H28: =IF($A28="","",SUMIFS(saisie_hebdo!$M:$M,saisie_hebdo!$I:$I,$A28)) | I28: =IF(OR($A28="",L28=0),"",IF(D28="Pourcentage",IF(H28>0,G28/H28*100,""),G28)) | J28: =IF(OR(I28="",F28="",F28=0),"",I28/F28) | K28: =IF(OR($A28="",L28=0),"",IF(_xlfn.MAXIFS(saisie_hebdo!$C:$C,saisie_hebdo!$I:$I,$A28)=0,"",_xlfn.MAXIFS(saisie_hebdo!$C:$C,saisie_hebdo!$I:$I,$A28))) | L28: =IF($A28="","",COUNTIFS(saisie_hebdo!$I:$I,$A28)) | M28: =IF($A28="","",IF(L28=0,"Non rapporté",IF(F28="","Suivi sans cible",IF(D28="Pourcentage",IF(I28>=F28,"Cible atteinte","Sous la cible"),IF(J28>=1,"Cible atteinte","En cours")))))
A29: =IFERROR(INDEX(ref_indicateurs!$A:$A,26)&"","") | B29: =IF($A29="","",INDEX(ref_indicateurs!$B:$B,MATCH($A29,ref_indicateurs!$A:$A,0))&"") | C29: =IF($A29="","",INDEX(ref_indicateurs!$C:$C,MATCH($A29,ref_indicateurs!$A:$A,0))&"") | D29: =IF($A29="","",INDEX(ref_indicateurs!$E:$E,MATCH($A29,ref_indicateurs!$A:$A,0))&"") | E29: =IF($A29="","",INDEX(ref_indicateurs!$M:$M,MATCH($A29,ref_indicateurs!$A:$A,0))&"") | F29: =IF($A29="","",IF(INDEX(ref_indicateurs!$O:$O,MATCH($A29,ref_indicateurs!$A:$A,0))="","",INDEX(ref_indicateurs!$O:$O,MATCH($A29,ref_indicateurs!$A:$A,0)))) | G29: =IF($A29="","",SUMIFS(saisie_hebdo!$L:$L,saisie_hebdo!$I:$I,$A29)) | H29: =IF($A29="","",SUMIFS(saisie_hebdo!$M:$M,saisie_hebdo!$I:$I,$A29)) | I29: =IF(OR($A29="",L29=0),"",IF(D29="Pourcentage",IF(H29>0,G29/H29*100,""),G29)) | J29: =IF(OR(I29="",F29="",F29=0),"",I29/F29) | K29: =IF(OR($A29="",L29=0),"",IF(_xlfn.MAXIFS(saisie_hebdo!$C:$C,saisie_hebdo!$I:$I,$A29)=0,"",_xlfn.MAXIFS(saisie_hebdo!$C:$C,saisie_hebdo!$I:$I,$A29))) | L29: =IF($A29="","",COUNTIFS(saisie_hebdo!$I:$I,$A29)) | M29: =IF($A29="","",IF(L29=0,"Non rapporté",IF(F29="","Suivi sans cible",IF(D29="Pourcentage",IF(I29>=F29,"Cible atteinte","Sous la cible"),IF(J29>=1,"Cible atteinte","En cours")))))
A30: =IFERROR(INDEX(ref_indicateurs!$A:$A,27)&"","") | B30: =IF($A30="","",INDEX(ref_indicateurs!$B:$B,MATCH($A30,ref_indicateurs!$A:$A,0))&"") | C30: =IF($A30="","",INDEX(ref_indicateurs!$C:$C,MATCH($A30,ref_indicateurs!$A:$A,0))&"") | D30: =IF($A30="","",INDEX(ref_indicateurs!$E:$E,MATCH($A30,ref_indicateurs!$A:$A,0))&"") | E30: =IF($A30="","",INDEX(ref_indicateurs!$M:$M,MATCH($A30,ref_indicateurs!$A:$A,0))&"") | F30: =IF($A30="","",IF(INDEX(ref_indicateurs!$O:$O,MATCH($A30,ref_indicateurs!$A:$A,0))="","",INDEX(ref_indicateurs!$O:$O,MATCH($A30,ref_indicateurs!$A:$A,0)))) | G30: =IF($A30="","",SUMIFS(saisie_hebdo!$L:$L,saisie_hebdo!$I:$I,$A30)) | H30: =IF($A30="","",SUMIFS(saisie_hebdo!$M:$M,saisie_hebdo!$I:$I,$A30)) | I30: =IF(OR($A30="",L30=0),"",IF(D30="Pourcentage",IF(H30>0,G30/H30*100,""),G30)) | J30: =IF(OR(I30="",F30="",F30=0),"",I30/F30) | K30: =IF(OR($A30="",L30=0),"",IF(_xlfn.MAXIFS(saisie_hebdo!$C:$C,saisie_hebdo!$I:$I,$A30)=0,"",_xlfn.MAXIFS(saisie_hebdo!$C:$C,saisie_hebdo!$I:$I,$A30))) | L30: =IF($A30="","",COUNTIFS(saisie_hebdo!$I:$I,$A30)) | M30: =IF($A30="","",IF(L30=0,"Non rapporté",IF(F30="","Suivi sans cible",IF(D30="Pourcentage",IF(I30>=F30,"Cible atteinte","Sous la cible"),IF(J30>=1,"Cible atteinte","En cours")))))
A31: =IFERROR(INDEX(ref_indicateurs!$A:$A,28)&"","") | B31: =IF($A31="","",INDEX(ref_indicateurs!$B:$B,MATCH($A31,ref_indicateurs!$A:$A,0))&"") | C31: =IF($A31="","",INDEX(ref_indicateurs!$C:$C,MATCH($A31,ref_indicateurs!$A:$A,0))&"") | D31: =IF($A31="","",INDEX(ref_indicateurs!$E:$E,MATCH($A31,ref_indicateurs!$A:$A,0))&"") | E31: =IF($A31="","",INDEX(ref_indicateurs!$M:$M,MATCH($A31,ref_indicateurs!$A:$A,0))&"") | F31: =IF($A31="","",IF(INDEX(ref_indicateurs!$O:$O,MATCH($A31,ref_indicateurs!$A:$A,0))="","",INDEX(ref_indicateurs!$O:$O,MATCH($A31,ref_indicateurs!$A:$A,0)))) | G31: =IF($A31="","",SUMIFS(saisie_hebdo!$L:$L,saisie_hebdo!$I:$I,$A31)) | H31: =IF($A31="","",SUMIFS(saisie_hebdo!$M:$M,saisie_hebdo!$I:$I,$A31)) | I31: =IF(OR($A31="",L31=0),"",IF(D31="Pourcentage",IF(H31>0,G31/H31*100,""),G31)) | J31: =IF(OR(I31="",F31="",F31=0),"",I31/F31) | K31: =IF(OR($A31="",L31=0),"",IF(_xlfn.MAXIFS(saisie_hebdo!$C:$C,saisie_hebdo!$I:$I,$A31)=0,"",_xlfn.MAXIFS(saisie_hebdo!$C:$C,saisie_hebdo!$I:$I,$A31))) | L31: =IF($A31="","",COUNTIFS(saisie_hebdo!$I:$I,$A31)) | M31: =IF($A31="","",IF(L31=0,"Non rapporté",IF(F31="","Suivi sans cible",IF(D31="Pourcentage",IF(I31>=F31,"Cible atteinte","Sous la cible"),IF(J31>=1,"Cible atteinte","En cours")))))
A32: =IFERROR(INDEX(ref_indicateurs!$A:$A,29)&"","") | B32: =IF($A32="","",INDEX(ref_indicateurs!$B:$B,MATCH($A32,ref_indicateurs!$A:$A,0))&"") | C32: =IF($A32="","",INDEX(ref_indicateurs!$C:$C,MATCH($A32,ref_indicateurs!$A:$A,0))&"") | D32: =IF($A32="","",INDEX(ref_indicateurs!$E:$E,MATCH($A32,ref_indicateurs!$A:$A,0))&"") | E32: =IF($A32="","",INDEX(ref_indicateurs!$M:$M,MATCH($A32,ref_indicateurs!$A:$A,0))&"") | F32: =IF($A32="","",IF(INDEX(ref_indicateurs!$O:$O,MATCH($A32,ref_indicateurs!$A:$A,0))="","",INDEX(ref_indicateurs!$O:$O,MATCH($A32,ref_indicateurs!$A:$A,0)))) | G32: =IF($A32="","",SUMIFS(saisie_hebdo!$L:$L,saisie_hebdo!$I:$I,$A32)) | H32: =IF($A32="","",SUMIFS(saisie_hebdo!$M:$M,saisie_hebdo!$I:$I,$A32)) | I32: =IF(OR($A32="",L32=0),"",IF(D32="Pourcentage",IF(H32>0,G32/H32*100,""),G32)) | J32: =IF(OR(I32="",F32="",F32=0),"",I32/F32) | K32: =IF(OR($A32="",L32=0),"",IF(_xlfn.MAXIFS(saisie_hebdo!$C:$C,saisie_hebdo!$I:$I,$A32)=0,"",_xlfn.MAXIFS(saisie_hebdo!$C:$C,saisie_hebdo!$I:$I,$A32))) | L32: =IF($A32="","",COUNTIFS(saisie_hebdo!$I:$I,$A32)) | M32: =IF($A32="","",IF(L32=0,"Non rapporté",IF(F32="","Suivi sans cible",IF(D32="Pourcentage",IF(I32>=F32,"Cible atteinte","Sous la cible"),IF(J32>=1,"Cible atteinte","En cours")))))
A33: =IFERROR(INDEX(ref_indicateurs!$A:$A,30)&"","") | B33: =IF($A33="","",INDEX(ref_indicateurs!$B:$B,MATCH($A33,ref_indicateurs!$A:$A,0))&"") | C33: =IF($A33="","",INDEX(ref_indicateurs!$C:$C,MATCH($A33,ref_indicateurs!$A:$A,0))&"") | D33: =IF($A33="","",INDEX(ref_indicateurs!$E:$E,MATCH($A33,ref_indicateurs!$A:$A,0))&"") | E33: =IF($A33="","",INDEX(ref_indicateurs!$M:$M,MATCH($A33,ref_indicateurs!$A:$A,0))&"") | F33: =IF($A33="","",IF(INDEX(ref_indicateurs!$O:$O,MATCH($A33,ref_indicateurs!$A:$A,0))="","",INDEX(ref_indicateurs!$O:$O,MATCH($A33,ref_indicateurs!$A:$A,0)))) | G33: =IF($A33="","",SUMIFS(saisie_hebdo!$L:$L,saisie_hebdo!$I:$I,$A33)) | H33: =IF($A33="","",SUMIFS(saisie_hebdo!$M:$M,saisie_hebdo!$I:$I,$A33)) | I33: =IF(OR($A33="",L33=0),"",IF(D33="Pourcentage",IF(H33>0,G33/H33*100,""),G33)) | J33: =IF(OR(I33="",F33="",F33=0),"",I33/F33) | K33: =IF(OR($A33="",L33=0),"",IF(_xlfn.MAXIFS(saisie_hebdo!$C:$C,saisie_hebdo!$I:$I,$A33)=0,"",_xlfn.MAXIFS(saisie_hebdo!$C:$C,saisie_hebdo!$I:$I,$A33))) | L33: =IF($A33="","",COUNTIFS(saisie_hebdo!$I:$I,$A33)) | M33: =IF($A33="","",IF(L33=0,"Non rapporté",IF(F33="","Suivi sans cible",IF(D33="Pourcentage",IF(I33>=F33,"Cible atteinte","Sous la cible"),IF(J33>=1,"Cible atteinte","En cours")))))
A34: =IFERROR(INDEX(ref_indicateurs!$A:$A,31)&"","") | B34: =IF($A34="","",INDEX(ref_indicateurs!$B:$B,MATCH($A34,ref_indicateurs!$A:$A,0))&"") | C34: =IF($A34="","",INDEX(ref_indicateurs!$C:$C,MATCH($A34,ref_indicateurs!$A:$A,0))&"") | D34: =IF($A34="","",INDEX(ref_indicateurs!$E:$E,MATCH($A34,ref_indicateurs!$A:$A,0))&"") | E34: =IF($A34="","",INDEX(ref_indicateurs!$M:$M,MATCH($A34,ref_indicateurs!$A:$A,0))&"") | F34: =IF($A34="","",IF(INDEX(ref_indicateurs!$O:$O,MATCH($A34,ref_indicateurs!$A:$A,0))="","",INDEX(ref_indicateurs!$O:$O,MATCH($A34,ref_indicateurs!$A:$A,0)))) | G34: =IF($A34="","",SUMIFS(saisie_hebdo!$L:$L,saisie_hebdo!$I:$I,$A34)) | H34: =IF($A34="","",SUMIFS(saisie_hebdo!$M:$M,saisie_hebdo!$I:$I,$A34)) | I34: =IF(OR($A34="",L34=0),"",IF(D34="Pourcentage",IF(H34>0,G34/H34*100,""),G34)) | J34: =IF(OR(I34="",F34="",F34=0),"",I34/F34) | K34: =IF(OR($A34="",L34=0),"",IF(_xlfn.MAXIFS(saisie_hebdo!$C:$C,saisie_hebdo!$I:$I,$A34)=0,"",_xlfn.MAXIFS(saisie_hebdo!$C:$C,saisie_hebdo!$I:$I,$A34))) | L34: =IF($A34="","",COUNTIFS(saisie_hebdo!$I:$I,$A34)) | M34: =IF($A34="","",IF(L34=0,"Non rapporté",IF(F34="","Suivi sans cible",IF(D34="Pourcentage",IF(I34>=F34,"Cible atteinte","Sous la cible"),IF(J34>=1,"Cible atteinte","En cours")))))
A35: =IFERROR(INDEX(ref_indicateurs!$A:$A,32)&"","") | B35: =IF($A35="","",INDEX(ref_indicateurs!$B:$B,MATCH($A35,ref_indicateurs!$A:$A,0))&"") | C35: =IF($A35="","",INDEX(ref_indicateurs!$C:$C,MATCH($A35,ref_indicateurs!$A:$A,0))&"") | D35: =IF($A35="","",INDEX(ref_indicateurs!$E:$E,MATCH($A35,ref_indicateurs!$A:$A,0))&"") | E35: =IF($A35="","",INDEX(ref_indicateurs!$M:$M,MATCH($A35,ref_indicateurs!$A:$A,0))&"") | F35: =IF($A35="","",IF(INDEX(ref_indicateurs!$O:$O,MATCH($A35,ref_indicateurs!$A:$A,0))="","",INDEX(ref_indicateurs!$O:$O,MATCH($A35,ref_indicateurs!$A:$A,0)))) | G35: =IF($A35="","",SUMIFS(saisie_hebdo!$L:$L,saisie_hebdo!$I:$I,$A35)) | H35: =IF($A35="","",SUMIFS(saisie_hebdo!$M:$M,saisie_hebdo!$I:$I,$A35)) | I35: =IF(OR($A35="",L35=0),"",IF(D35="Pourcentage",IF(H35>0,G35/H35*100,""),G35)) | J35: =IF(OR(I35="",F35="",F35=0),"",I35/F35) | K35: =IF(OR($A35="",L35=0),"",IF(_xlfn.MAXIFS(saisie_hebdo!$C:$C,saisie_hebdo!$I:$I,$A35)=0,"",_xlfn.MAXIFS(saisie_hebdo!$C:$C,saisie_hebdo!$I:$I,$A35))) | L35: =IF($A35="","",COUNTIFS(saisie_hebdo!$I:$I,$A35)) | M35: =IF($A35="","",IF(L35=0,"Non rapporté",IF(F35="","Suivi sans cible",IF(D35="Pourcentage",IF(I35>=F35,"Cible atteinte","Sous la cible"),IF(J35>=1,"Cible atteinte","En cours")))))
A36: =IFERROR(INDEX(ref_indicateurs!$A:$A,33)&"","") | B36: =IF($A36="","",INDEX(ref_indicateurs!$B:$B,MATCH($A36,ref_indicateurs!$A:$A,0))&"") | C36: =IF($A36="","",INDEX(ref_indicateurs!$C:$C,MATCH($A36,ref_indicateurs!$A:$A,0))&"") | D36: =IF($A36="","",INDEX(ref_indicateurs!$E:$E,MATCH($A36,ref_indicateurs!$A:$A,0))&"") | E36: =IF($A36="","",INDEX(ref_indicateurs!$M:$M,MATCH($A36,ref_indicateurs!$A:$A,0))&"") | F36: =IF($A36="","",IF(INDEX(ref_indicateurs!$O:$O,MATCH($A36,ref_indicateurs!$A:$A,0))="","",INDEX(ref_indicateurs!$O:$O,MATCH($A36,ref_indicateurs!$A:$A,0)))) | G36: =IF($A36="","",SUMIFS(saisie_hebdo!$L:$L,saisie_hebdo!$I:$I,$A36)) | H36: =IF($A36="","",SUMIFS(saisie_hebdo!$M:$M,saisie_hebdo!$I:$I,$A36)) | I36: =IF(OR($A36="",L36=0),"",IF(D36="Pourcentage",IF(H36>0,G36/H36*100,""),G36)) | J36: =IF(OR(I36="",F36="",F36=0),"",I36/F36) | K36: =IF(OR($A36="",L36=0),"",IF(_xlfn.MAXIFS(saisie_hebdo!$C:$C,saisie_hebdo!$I:$I,$A36)=0,"",_xlfn.MAXIFS(saisie_hebdo!$C:$C,saisie_hebdo!$I:$I,$A36))) | L36: =IF($A36="","",COUNTIFS(saisie_hebdo!$I:$I,$A36)) | M36: =IF($A36="","",IF(L36=0,"Non rapporté",IF(F36="","Suivi sans cible",IF(D36="Pourcentage",IF(I36>=F36,"Cible atteinte","Sous la cible"),IF(J36>=1,"Cible atteinte","En cours")))))
A37: =IFERROR(INDEX(ref_indicateurs!$A:$A,34)&"","") | B37: =IF($A37="","",INDEX(ref_indicateurs!$B:$B,MATCH($A37,ref_indicateurs!$A:$A,0))&"") | C37: =IF($A37="","",INDEX(ref_indicateurs!$C:$C,MATCH($A37,ref_indicateurs!$A:$A,0))&"") | D37: =IF($A37="","",INDEX(ref_indicateurs!$E:$E,MATCH($A37,ref_indicateurs!$A:$A,0))&"") | E37: =IF($A37="","",INDEX(ref_indicateurs!$M:$M,MATCH($A37,ref_indicateurs!$A:$A,0))&"") | F37: =IF($A37="","",IF(INDEX(ref_indicateurs!$O:$O,MATCH($A37,ref_indicateurs!$A:$A,0))="","",INDEX(ref_indicateurs!$O:$O,MATCH($A37,ref_indicateurs!$A:$A,0)))) | G37: =IF($A37="","",SUMIFS(saisie_hebdo!$L:$L,saisie_hebdo!$I:$I,$A37)) | H37: =IF($A37="","",SUMIFS(saisie_hebdo!$M:$M,saisie_hebdo!$I:$I,$A37)) | I37: =IF(OR($A37="",L37=0),"",IF(D37="Pourcentage",IF(H37>0,G37/H37*100,""),G37)) | J37: =IF(OR(I37="",F37="",F37=0),"",I37/F37) | K37: =IF(OR($A37="",L37=0),"",IF(_xlfn.MAXIFS(saisie_hebdo!$C:$C,saisie_hebdo!$I:$I,$A37)=0,"",_xlfn.MAXIFS(saisie_hebdo!$C:$C,saisie_hebdo!$I:$I,$A37))) | L37: =IF($A37="","",COUNTIFS(saisie_hebdo!$I:$I,$A37)) | M37: =IF($A37="","",IF(L37=0,"Non rapporté",IF(F37="","Suivi sans cible",IF(D37="Pourcentage",IF(I37>=F37,"Cible atteinte","Sous la cible"),IF(J37>=1,"Cible atteinte","En cours")))))
A38: =IFERROR(INDEX(ref_indicateurs!$A:$A,35)&"","") | B38: =IF($A38="","",INDEX(ref_indicateurs!$B:$B,MATCH($A38,ref_indicateurs!$A:$A,0))&"") | C38: =IF($A38="","",INDEX(ref_indicateurs!$C:$C,MATCH($A38,ref_indicateurs!$A:$A,0))&"") | D38: =IF($A38="","",INDEX(ref_indicateurs!$E:$E,MATCH($A38,ref_indicateurs!$A:$A,0))&"") | E38: =IF($A38="","",INDEX(ref_indicateurs!$M:$M,MATCH($A38,ref_indicateurs!$A:$A,0))&"") | F38: =IF($A38="","",IF(INDEX(ref_indicateurs!$O:$O,MATCH($A38,ref_indicateurs!$A:$A,0))="","",INDEX(ref_indicateurs!$O:$O,MATCH($A38,ref_indicateurs!$A:$A,0)))) | G38: =IF($A38="","",SUMIFS(saisie_hebdo!$L:$L,saisie_hebdo!$I:$I,$A38)) | H38: =IF($A38="","",SUMIFS(saisie_hebdo!$M:$M,saisie_hebdo!$I:$I,$A38)) | I38: =IF(OR($A38="",L38=0),"",IF(D38="Pourcentage",IF(H38>0,G38/H38*100,""),G38)) | J38: =IF(OR(I38="",F38="",F38=0),"",I38/F38) | K38: =IF(OR($A38="",L38=0),"",IF(_xlfn.MAXIFS(saisie_hebdo!$C:$C,saisie_hebdo!$I:$I,$A38)=0,"",_xlfn.MAXIFS(saisie_hebdo!$C:$C,saisie_hebdo!$I:$I,$A38))) | L38: =IF($A38="","",COUNTIFS(saisie_hebdo!$I:$I,$A38)) | M38: =IF($A38="","",IF(L38=0,"Non rapporté",IF(F38="","Suivi sans cible",IF(D38="Pourcentage",IF(I38>=F38,"Cible atteinte","Sous la cible"),IF(J38>=1,"Cible atteinte","En cours")))))
A39: =IFERROR(INDEX(ref_indicateurs!$A:$A,36)&"","") | B39: =IF($A39="","",INDEX(ref_indicateurs!$B:$B,MATCH($A39,ref_indicateurs!$A:$A,0))&"") | C39: =IF($A39="","",INDEX(ref_indicateurs!$C:$C,MATCH($A39,ref_indicateurs!$A:$A,0))&"") | D39: =IF($A39="","",INDEX(ref_indicateurs!$E:$E,MATCH($A39,ref_indicateurs!$A:$A,0))&"") | E39: =IF($A39="","",INDEX(ref_indicateurs!$M:$M,MATCH($A39,ref_indicateurs!$A:$A,0))&"") | F39: =IF($A39="","",IF(INDEX(ref_indicateurs!$O:$O,MATCH($A39,ref_indicateurs!$A:$A,0))="","",INDEX(ref_indicateurs!$O:$O,MATCH($A39,ref_indicateurs!$A:$A,0)))) | G39: =IF($A39="","",SUMIFS(saisie_hebdo!$L:$L,saisie_hebdo!$I:$I,$A39)) | H39: =IF($A39="","",SUMIFS(saisie_hebdo!$M:$M,saisie_hebdo!$I:$I,$A39)) | I39: =IF(OR($A39="",L39=0),"",IF(D39="Pourcentage",IF(H39>0,G39/H39*100,""),G39)) | J39: =IF(OR(I39="",F39="",F39=0),"",I39/F39) | K39: =IF(OR($A39="",L39=0),"",IF(_xlfn.MAXIFS(saisie_hebdo!$C:$C,saisie_hebdo!$I:$I,$A39)=0,"",_xlfn.MAXIFS(saisie_hebdo!$C:$C,saisie_hebdo!$I:$I,$A39))) | L39: =IF($A39="","",COUNTIFS(saisie_hebdo!$I:$I,$A39)) | M39: =IF($A39="","",IF(L39=0,"Non rapporté",IF(F39="","Suivi sans cible",IF(D39="Pourcentage",IF(I39>=F39,"Cible atteinte","Sous la cible"),IF(J39>=1,"Cible atteinte","En cours")))))
A40: =IFERROR(INDEX(ref_indicateurs!$A:$A,37)&"","") | B40: =IF($A40="","",INDEX(ref_indicateurs!$B:$B,MATCH($A40,ref_indicateurs!$A:$A,0))&"") | C40: =IF($A40="","",INDEX(ref_indicateurs!$C:$C,MATCH($A40,ref_indicateurs!$A:$A,0))&"") | D40: =IF($A40="","",INDEX(ref_indicateurs!$E:$E,MATCH($A40,ref_indicateurs!$A:$A,0))&"") | E40: =IF($A40="","",INDEX(ref_indicateurs!$M:$M,MATCH($A40,ref_indicateurs!$A:$A,0))&"") | F40: =IF($A40="","",IF(INDEX(ref_indicateurs!$O:$O,MATCH($A40,ref_indicateurs!$A:$A,0))="","",INDEX(ref_indicateurs!$O:$O,MATCH($A40,ref_indicateurs!$A:$A,0)))) | G40: =IF($A40="","",SUMIFS(saisie_hebdo!$L:$L,saisie_hebdo!$I:$I,$A40)) | H40: =IF($A40="","",SUMIFS(saisie_hebdo!$M:$M,saisie_hebdo!$I:$I,$A40)) | I40: =IF(OR($A40="",L40=0),"",IF(D40="Pourcentage",IF(H40>0,G40/H40*100,""),G40)) | J40: =IF(OR(I40="",F40="",F40=0),"",I40/F40) | K40: =IF(OR($A40="",L40=0),"",IF(_xlfn.MAXIFS(saisie_hebdo!$C:$C,saisie_hebdo!$I:$I,$A40)=0,"",_xlfn.MAXIFS(saisie_hebdo!$C:$C,saisie_hebdo!$I:$I,$A40))) | L40: =IF($A40="","",COUNTIFS(saisie_hebdo!$I:$I,$A40)) | M40: =IF($A40="","",IF(L40=0,"Non rapporté",IF(F40="","Suivi sans cible",IF(D40="Pourcentage",IF(I40>=F40,"Cible atteinte","Sous la cible"),IF(J40>=1,"Cible atteinte","En cours")))))
A41: =IFERROR(INDEX(ref_indicateurs!$A:$A,38)&"","") | B41: =IF($A41="","",INDEX(ref_indicateurs!$B:$B,MATCH($A41,ref_indicateurs!$A:$A,0))&"") | C41: =IF($A41="","",INDEX(ref_indicateurs!$C:$C,MATCH($A41,ref_indicateurs!$A:$A,0))&"") | D41: =IF($A41="","",INDEX(ref_indicateurs!$E:$E,MATCH($A41,ref_indicateurs!$A:$A,0))&"") | E41: =IF($A41="","",INDEX(ref_indicateurs!$M:$M,MATCH($A41,ref_indicateurs!$A:$A,0))&"") | F41: =IF($A41="","",IF(INDEX(ref_indicateurs!$O:$O,MATCH($A41,ref_indicateurs!$A:$A,0))="","",INDEX(ref_indicateurs!$O:$O,MATCH($A41,ref_indicateurs!$A:$A,0)))) | G41: =IF($A41="","",SUMIFS(saisie_hebdo!$L:$L,saisie_hebdo!$I:$I,$A41)) | H41: =IF($A41="","",SUMIFS(saisie_hebdo!$M:$M,saisie_hebdo!$I:$I,$A41)) | I41: =IF(OR($A41="",L41=0),"",IF(D41="Pourcentage",IF(H41>0,G41/H41*100,""),G41)) | J41: =IF(OR(I41="",F41="",F41=0),"",I41/F41) | K41: =IF(OR($A41="",L41=0),"",IF(_xlfn.MAXIFS(saisie_hebdo!$C:$C,saisie_hebdo!$I:$I,$A41)=0,"",_xlfn.MAXIFS(saisie_hebdo!$C:$C,saisie_hebdo!$I:$I,$A41))) | L41: =IF($A41="","",COUNTIFS(saisie_hebdo!$I:$I,$A41)) | M41: =IF($A41="","",IF(L41=0,"Non rapporté",IF(F41="","Suivi sans cible",IF(D41="Pourcentage",IF(I41>=F41,"Cible atteinte","Sous la cible"),IF(J41>=1,"Cible atteinte","En cours")))))
...

Sheet saisie_hebdo
A1: annee | B1: periode | C1: semaine_iso | D1: date_debut | E1: date_fin | F1: ip | G1: province | H1: zone_sante | I1: id_indicateur | J1: libelle_indicateur | K1: desagregation | L1: numerateur | M1: denominateur | N1: valeur | O1: source_saisie | P1: saisi_par | Q1: date_saisie | R1: commentaire
A2: 2026 | B2: S41 | C2: 41 | D2: 46300 | E2: 46306 | F2: ADRA | G2: Ituri | H2: Rwampara | I2: SURV-02 | J2: Contacts suivis chaque jour pendant les 21 jours | L2: 1830 | M2: 2010 | N2: =IF(M2="",L2,IF(M2=0,"",L2/M2*100)) | O2: ODK | P2: Nom du point focal | Q2: 46306 | R2: Ligne d'exemple : à supprimer

Sheet sbc_activites
A1: date | B1: ip | C1: province | D1: zone_sante | E1: aire_sante | F1: village_quartier | G1: type_site | H1: nb_seances_prevues | I1: nb_seances_realisees | J1: nb_menages_prevus | K1: nb_menages_visites | L1: nb_vad | M1: nb_causeries | N1: nb_ecoute_negociation | O1: nb_debats_dialogues | P1: nb_sketchs | Q1: nb_emissions_radio | R1: nb_emissions_interactives | S1: nb_spots_radio | T1: themes | U1: sensibilises_h | V1: sensibilises_f | W1: alertes_malades | X1: alertes_deces | Y1: alertes_malades_notifiees_24h | Z1: alertes_deces_notifiees_24h | AA1: alertes_investiguees_24h | AB1: nb_visiteurs | AC1: provenance_visiteurs | AD1: malades_orientes_fosa | AE1: malades_arrives_fosa | AF1: malades_orientes_ct_cte | AG1: commentaire
A2: 46305 | B2: ADRA | C2: Ituri | D2: Rwampara | E2: Dele | F2: Village X | G2: Marché | H2: 2 | I2: 2 | L2: 0 | M2: 2 | N2: 0 | O2: 0 | P2: 0 | Q2: 0 | R2: 0 | S2: 0 | T2: Signes de la MVE ; numéro vert 151 | U2: 48 | V2: 61 | W2: 1 | X2: 0 | Y2: 1 | Z2: 0 | AA2: 1 | AB2: 3 | AC2: Bunia (ZS Bunia) | AD2: 1 | AE2: 1 | AF2: 0 | AG2: Ligne d'exemple : à supprimer

Sheet sbc_synthese_as
A1: date | B1: ip | C1: province | D1: zone_sante | E1: aire_sante | F1: reco_attendus | G1: reco_ayant_travaille | H1: contacts_listes_h | I1: contacts_listes_f | J1: contacts_sous_suivi_h | K1: contacts_sous_suivi_f | L1: contacts_vus_h | M1: contacts_vus_f | N1: contacts_symptomatiques | O1: contacts_symptomatiques_referes_24h | P1: contacts_fin_suivi_21j | Q1: contacts_perdus_de_vue | R1: contacts_sensibilises_vaccination | S1: contacts_vaccines | T1: deces_communautaires_notifies | U1: deces_communautaires_swabes | V1: deces_communautaires_eds | W1: alertes_verifiees_24h | X1: reticences_enregistrees | Y1: reticences_levees_meme_jour | Z1: reticences_levees_48h | AA1: rumeurs_enregistrees | AB1: rumeurs_traitees_48h | AC1: alertes_sante_animale | AD1: feedback_majeur | AE1: visa_as | AF1: visa_bcz
A2: 46305 | B2: ADRA | C2: Ituri | D2: Rwampara | E2: Dele | F2: 25 | G2: 22 | H2: 3 | I2: 4 | J2: 40 | K2: 52 | L2: 38 | M2: 49 | N2: 1 | O2: 1 | P2: 6 | Q2: 0 | R2: 0 | S2: 0 | T2: 1 | U2: 1 | V2: 1 | W2: 1 | X2: 2 | Y2: 1 | Z2: 2 | AA2: 3 | AB2: 2 | AC2: 0 | AD2: Rumeur : « le CTE ne nourrit pas les malades » | AE2: O | AF2: O

Sheet reunions
A1: id_reunion | B1: date | C1: niveau | D1: lieu | E1: objet | F1: duree_min | G1: nb_participants | H1: representant_cgpp | I1: fichier_rapport | J1: liste_presence_complete
A2: 20261012-ZS-RWAMPARA | B2: 46307 | C2: Zone de santé | D2: BCZ Rwampara | E2: Réunion de coordination de la ZS | F2: 60 | G2: 18 | H2: Point focal ADRA | I2: CR_ZS_Rwampara_2026-10-12.docx | J2: O

Sheet points_action
A1: id_action | B1: id_reunion | C1: action | D1: concerne_cgpp | E1: responsable | F1: echeance | G1: statut | H1: date_statut | I1: commentaire
A2: 20261012-ZS-RWAMPARA-01 | B2: 20261012-ZS-RWAMPARA | C2: Relancer les RECO de l'AS Dele pour la saisie quotidienne | D2: O | E2: Superviseur ADRA | F2: 46309 | G2: En cours | H2: 46307 | I2: Ligne d'exemple : à supprimer

Sheet sitrep_notes
A1: date_rapport | B1: section | C1: ordre | D1: texte | E1: auteur
A2: 46305 | B2: Faits marquants | C2: 1 | D2: Exemple : 35 RECO de l'AS de Nzere briefés sur l'approche village. | E2: Nom de l'auteur

Sheet qc_suivi
A1: id_anomalie | B1: date_detection | C1: regle | D1: source | E1: objet | F1: description | G1: gravite | H1: responsable | I1: statut | J1: date_resolution
A2: SR-11 | SitRep 146 | Taux d'occupation | B2: 46307 | C2: SR-11 | D2: SitRep 146 | E2: Taux d'occupation Nord-Kivu | F2: 84,2 % publié pour 169/209 (80,9 %) | G2: Majeure | H2: Data manager INSP | I2: Ouverte

Sheet ref_zones
A1: province | B1: zone_sante | C1: code_zs | D1: ip_cgpp | E1: statut_cgpp | F1: population | G1: source
A2: Nord-Kivu | B2: Goma | D2: WV | E2: intervention | G2: config.yaml
A3: Nord-Kivu | B3: Karisimbi | D3: WV | E3: intervention | G3: config.yaml
A4: Nord-Kivu | B4: Rwanguba | D4: WV | E4: intervention | G4: config.yaml
A5: Nord-Kivu | B5: Kalunguta | D5: WV | E5: intervention | G5: config.yaml
A6: Nord-Kivu | B6: Mutwanga | D6: WV | E6: intervention | G6: config.yaml
A7: Sud-Kivu | B7: Uvira | D7: WV | E7: intervention | G7: config.yaml
A8: Sud-Kivu | B8: Nundu | D8: WV | E8: intervention | G8: config.yaml
A9: Sud-Kivu | B9: Nyangezi | D9: WV | E9: intervention | G9: config.yaml
A10: Ituri | B10: Rwampara | D10: ADRA | E10: intervention | G10: config.yaml
A11: Ituri | B11: Lita | D11: ADRA | E11: intervention | G11: config.yaml
A12: Nord-Kivu | B12: Beni | D12: IMC | E12: intervention | G12: config.yaml
A13: Nord-Kivu | B13: Katwa | D13: IMC | E13: intervention | G13: config.yaml

Sheet ref_partenaires
A1: code_ip | B1: nom | C1: role | D1: provinces | E1: point_focal | F1: email_point_focal
A2: WV | B2: World Vision RDC | C2: Partenaire de mise en oeuvre
A3: ADRA | B3: Adventist Development and Relief Agency | C3: Partenaire de mise en oeuvre
A4: IMC | B4: International Medical Corps | C4: Partenaire de mise en oeuvre
A5: IRC | B5: International Rescue Committee | C5: Partenaire de mise en oeuvre

Sheet ref_indicateurs
A1: id_indicateur | B1: pilier | C1: libelle_fr | D1: libelle_en | E1: type | F1: niveau | G1: numerateur | H1: denominateur | I1: source_donnees | J1: champ_source | K1: frequence | L1: desagregation | M1: cible_dos | N1: cible_tranche5 | O1: cible_dos_num | P1: cible_t5_num | Q1: seuil_alerte | R1: id_barclay | S1: id_cadre_global | T1: statut | U1: priorite | V1: commentaire
A2: COORD-01 | B2: COORD | C2: Matrices 4W élaborées et mises à jour | D2: # of 4W matrices developed and updated | E2: Nombre | F2: Tier 2 | G2: Matrices 4W (1 nationale, 3 provinciales) mises à jour dans le mois | H2: N/A | I2: Matrices 4W | K2: Mensuelle | L2: Niveau (national, provincial) | M2: 4 | O2: 4 | R2: 1.1 | T2: existant | U2: 2
A3: COORD-02 | B3: COORD | C3: Matrice des partenaires CGPP tenue à jour | D3: # of CGPP partner matrices maintained | E3: Nombre | F3: Tier 2 | G3: Matrices partenaires mises à jour | H3: N/A | I3: Matrice partenaires | K3: Mensuelle | M3: 1 | O3: 1 | R3: 1.2 | T3: existant | U3: 3
A4: COORD-03 | B4: COORD | C4: Réunions de coordination auxquelles CGPP a participé ou qu'il a appuyées | D4: # of coordination meetings participated in or supported | E4: Nombre | F4: Tier 2 | G4: Réunions avec compte rendu et liste de présence complète | H4: N/A | I4: Feuille « reunions » de la base | J4: reunions | K4: Mensuelle | L4: Niveau, province | M4: 90 | O4: 90 | R4: 1.3 | S4: 21 | T4: à corriger | U4: 1 | V4: Ne compter que les réunions documentées (compte rendu + liste de présence complète).
A5: COORD-04 | B5: COORD | C5: Réunions bilatérales ou conjointes avec les partenaires financés par le DOS | D5: # of bilateral/joint coordination meetings with DOS-funded partners | E5: Nombre | F5: Tier 2 | G5: Réunions bilatérales/conjointes tenues | H5: N/A | I5: Notes de réunion | J5: reunions | K5: Mensuelle | L5: Partenaire | M5: 12 | O5: 12 | R5: 1.4 | T5: existant | U5: 3
A6: COORD-05 | B6: COORD | C6: Réunions hebdomadaires de coordination CGPP | D6: # of weekly CGPP coordination meetings conducted | E6: Nombre | F6: Tier 2 | G6: Réunions internes hebdomadaires tenues | H6: N/A | I6: Comptes rendus | J6: reunions | K6: Hebdomadaire | M6: 16 | O6: 16 | R6: 1.5 | T6: existant | U6: 3
A7: COORD-06 | B7: COORD | C7: Réunions de revue provinciales | D7: # of provincial review meetings conducted | E7: Nombre | F7: Tier 2 | G7: Revues provinciales tenues | H7: N/A | I7: Rapports de revue | J7: reunions | K7: Mensuelle | L7: Province | M7: 12 | O7: 12 | R7: 1.6 | T7: existant | U7: 3
A8: COORD-07 | B8: COORD | C8: Outil harmonisé de suivi EIR et de rapportage mis en place | D8: # of RRT/data reporting trackers established | E8: Nombre | F8: Tier 2 | G8: Outil en service | H8: N/A | I8: Outil de suivi | K8: Mensuelle | M8: 1 | O8: 1 | R8: 1.7 | T8: existant | U8: 1 | V8: La base Excel normalisée et la chaîne Python décrites dans ce rapport peuvent tenir ce rôle.
A9: COORD-08 | B9: COORD | C9: Mises à jour quotidiennes de terrain transmises | D9: # of daily field updates submitted | E9: Nombre | F9: Tier 2 | G9: Mises à jour quotidiennes transmises | H9: N/A | I9: Journal des envois | K9: Quotidienne | L9: IP | M9: 110 | O9: 110 | R9: 1.8 | T9: existant | U9: 2
A10: COORD-09 | B10: COORD | C10: Mises à jour hebdomadaires de coordination transmises | D10: # of weekly coordination updates submitted | E10: Nombre | F10: Tier 2 | G10: Mises à jour hebdomadaires transmises | H10: N/A | I10: Journal des envois | K10: Hebdomadaire | M10: 16 | O10: 16 | R10: 1.9 | T10: à corriger | U10: 2 | V10: Le plan DOS indique 16 (extrants du pilier 1) et 18 (activité 1.5) : arrêter une seule cible.
A11: COORD-10 | B11: COORD | C11: Séances de négociation ou de médiation de crise avec le pilier CREC | D11: # of crisis negotiation/mediation sessions conducted with CREC Pillar | E11: Nombre | F11: Tier 2 | G11: Séances tenues | H11: N/A | I11: Rapports de négociation | K11: Selon besoin | M11: 4 | O11: 4 | R11: 1.10 | T11: existant | U11: 3
A12: COORD-11 | B12: COORD | C12: Réunions de coordination transfrontalière | D12: # of cross-border coordination meetings held | E12: Nombre | F12: Tier 2 | G12: Réunions transfrontalières tenues | H12: N/A | I12: Comptes rendus | J12: reunions | K12: Mensuelle | L12: Frontière | M12: 6 | N12: 100 échanges transfrontaliers ou interprovinciaux | O12: 6 | R12: 1.11 | T12: existant | U12: 3
A13: COORD-12 | B13: COORD | C13: Points d'action des réunions réalisés dans les délais | D13: % of action points generated and followed up | E13: Pourcentage | F13: Tier 1 | G13: Points d'action réalisés à l'échéance | H13: Points d'action arrivés à échéance | I13: Feuille « points_action » de la base | J13: points_action | K13: Mensuelle | L13: Niveau de réunion | M13: 100 % | O13: 100 | Q13: < 70 % : rouge | R13: 1.12 | T13: à corriger | U13: 1 | V13: Intitulé « # » alors que c'est un pourcentage ; cible codée 1 ; les comptes rendus actuels ne listent pas de points d'action.
